no exception occured
I am inside finally block
test completed
